# Snapshot report for `built-ins/Promise/reject/index.js`

The actual snapshot is saved in `index.js.snap`.

Generated by [AVA](https://avajs.dev).

## built-ins/Promise/reject/S25.4.4.4_A1.1_T1.js

> | Test Stage | Status | Details |
> | :-- | :-- | :-- |
> | Load | ✅ Pass |  |
> | Transpile | ✅ Pass |  |
> | Compile | ✅ Pass |  |
> | Execute | ❌ Fail | An error occurred while executing the test program. |

    Error {
      message: 'Uncaught ReferenceError: "Promise" is not defined',
    }

## built-ins/Promise/reject/S25.4.4.4_A2.1_T1.js

> | Test Stage | Status | Details |
> | :-- | :-- | :-- |
> | Load | ❌ Fail | An error occurred while loading the test from the `test262` folder. |
> | Transpile | ⬜ Skip | *This stage did not run.* |
> | Compile | ⬜ Skip | *This stage did not run.* |
> | Execute | ⬜ Skip | *This stage did not run.* |

    LoaderError {
      message: 'Async/await, event loop, etc. are not implemented, and thus, tests with the `async` flag are not supported at this time.',
    }

## built-ins/Promise/reject/S25.4.4.4_A3.1_T1.js

> | Test Stage | Status | Details |
> | :-- | :-- | :-- |
> | Load | ✅ Pass |  |
> | Transpile | ✅ Pass |  |
> | Compile | ✅ Pass |  |
> | Execute | ❌ Fail | An error occurred while executing the test program. |

    Error {
      message: 'Uncaught Test262Error: Expected a undefined but got a different error constructor with the same name',
    }

## built-ins/Promise/reject/capability-executor-called-twice.js

> | Test Stage | Status | Details |
> | :-- | :-- | :-- |
> | Load | ✅ Pass |  |
> | Transpile | ✅ Pass |  |
> | Compile | ✅ Pass |  |
> | Execute | ❌ Fail | An error occurred while executing the test program. |

    Error {
      message: 'Uncaught ReferenceError: "Promise" is not defined',
    }

## built-ins/Promise/reject/capability-executor-not-callable.js

> | Test Stage | Status | Details |
> | :-- | :-- | :-- |
> | Load | ✅ Pass |  |
> | Transpile | ✅ Pass |  |
> | Compile | ✅ Pass |  |
> | Execute | ❌ Fail | An error occurred while executing the test program. |

    Error {
      message: 'Uncaught Test262Error: Expected a undefined but got a different error constructor with the same name',
    }

## built-ins/Promise/reject/capability-invocation-error.js

> | Test Stage | Status | Details |
> | :-- | :-- | :-- |
> | Load | ✅ Pass |  |
> | Transpile | ✅ Pass |  |
> | Compile | ❌ Fail | An error occurred while compiling the test with `g++`. |
> | Execute | ⬜ Skip | *This stage did not run.* |

    Error {
      message: `<stdin>:261:19: error: redefinition of '_anonymous_13'␊
      shared_ptr<Value> _anonymous_13 (shared_ptr<Scope> scope, shared_ptr<Value> _this, vector<shared_ptr<Value> > arguments) {␊
                        ^␊
      <stdin>:237:19: note: previous definition is here␊
      shared_ptr<Value> _anonymous_13 (shared_ptr<Scope> scope, shared_ptr<Value> _this, vector<shared_ptr<Value> > arguments) {␊
                        ^␊
      <stdin>:267:19: error: redefinition of '_anonymous_14'␊
      shared_ptr<Value> _anonymous_14 (shared_ptr<Scope> scope, shared_ptr<Value> _this, vector<shared_ptr<Value> > arguments) {␊
                        ^␊
      <stdin>:243:19: note: previous definition is here␊
      shared_ptr<Value> _anonymous_14 (shared_ptr<Scope> scope, shared_ptr<Value> _this, vector<shared_ptr<Value> > arguments) {␊
                        ^␊
      <stdin>:272:19: error: redefinition of '_anonymous_15'␊
      shared_ptr<Value> _anonymous_15 (shared_ptr<Scope> scope, shared_ptr<Value> _this, vector<shared_ptr<Value> > arguments) {␊
                        ^␊
      <stdin>:248:19: note: previous definition is here␊
      shared_ptr<Value> _anonymous_15 (shared_ptr<Scope> scope, shared_ptr<Value> _this, vector<shared_ptr<Value> > arguments) {␊
                        ^␊
      <stdin>:276:19: error: redefinition of '_anonymous_16'␊
      shared_ptr<Value> _anonymous_16 (shared_ptr<Scope> scope, shared_ptr<Value> _this, vector<shared_ptr<Value> > arguments) {␊
                        ^␊
      <stdin>:252:19: note: previous definition is here␊
      shared_ptr<Value> _anonymous_16 (shared_ptr<Scope> scope, shared_ptr<Value> _this, vector<shared_ptr<Value> > arguments) {␊
                        ^␊
      4 errors generated.`,
    }

## built-ins/Promise/reject/capability-invocation.js

> | Test Stage | Status | Details |
> | :-- | :-- | :-- |
> | Load | ✅ Pass |  |
> | Transpile | ✅ Pass |  |
> | Compile | ❌ Fail | An error occurred while compiling the test with `g++`. |
> | Execute | ⬜ Skip | *This stage did not run.* |

    Error {
      message: `<stdin>:275:19: error: redefinition of '_anonymous_13'␊
      shared_ptr<Value> _anonymous_13 (shared_ptr<Scope> scope, shared_ptr<Value> _this, vector<shared_ptr<Value> > arguments) {␊
                        ^␊
      <stdin>:249:19: note: previous definition is here␊
      shared_ptr<Value> _anonymous_13 (shared_ptr<Scope> scope, shared_ptr<Value> _this, vector<shared_ptr<Value> > arguments) {␊
                        ^␊
      <stdin>:279:19: error: redefinition of '_anonymous_14'␊
      shared_ptr<Value> _anonymous_14 (shared_ptr<Scope> scope, shared_ptr<Value> _this, vector<shared_ptr<Value> > arguments) {␊
                        ^␊
      <stdin>:253:19: note: previous definition is here␊
      shared_ptr<Value> _anonymous_14 (shared_ptr<Scope> scope, shared_ptr<Value> _this, vector<shared_ptr<Value> > arguments) {␊
                        ^␊
      <stdin>:285:19: error: redefinition of '_anonymous_15'␊
      shared_ptr<Value> _anonymous_15 (shared_ptr<Scope> scope, shared_ptr<Value> _this, vector<shared_ptr<Value> > arguments) {␊
                        ^␊
      <stdin>:259:19: note: previous definition is here␊
      shared_ptr<Value> _anonymous_15 (shared_ptr<Scope> scope, shared_ptr<Value> _this, vector<shared_ptr<Value> > arguments) {␊
                        ^␊
      <stdin>:290:19: error: redefinition of '_anonymous_16'␊
      shared_ptr<Value> _anonymous_16 (shared_ptr<Scope> scope, shared_ptr<Value> _this, vector<shared_ptr<Value> > arguments) {␊
                        ^␊
      <stdin>:264:19: note: previous definition is here␊
      shared_ptr<Value> _anonymous_16 (shared_ptr<Scope> scope, shared_ptr<Value> _this, vector<shared_ptr<Value> > arguments) {␊
                        ^␊
      <stdin>:295:19: error: redefinition of '_anonymous_17'␊
      shared_ptr<Value> _anonymous_17 (shared_ptr<Scope> scope, shared_ptr<Value> _this, vector<shared_ptr<Value> > arguments) {␊
                        ^␊
      <stdin>:269:19: note: previous definition is here␊
      shared_ptr<Value> _anonymous_17 (shared_ptr<Scope> scope, shared_ptr<Value> _this, vector<shared_ptr<Value> > arguments) {␊
                        ^␊
      5 errors generated.`,
    }

## built-ins/Promise/reject/ctx-ctor-throws.js

> | Test Stage | Status | Details |
> | :-- | :-- | :-- |
> | Load | ✅ Pass |  |
> | Transpile | ✅ Pass |  |
> | Compile | ❌ Fail | An error occurred while compiling the test with `g++`. |
> | Execute | ⬜ Skip | *This stage did not run.* |

    Error {
      message: `<stdin>:240:19: error: redefinition of '_anonymous_10'␊
      shared_ptr<Value> _anonymous_10 (shared_ptr<Scope> scope, shared_ptr<Value> _this, vector<shared_ptr<Value> > arguments) {␊
                        ^␊
      <stdin>:231:19: note: previous definition is here␊
      shared_ptr<Value> _anonymous_10 (shared_ptr<Scope> scope, shared_ptr<Value> _this, vector<shared_ptr<Value> > arguments) {␊
                        ^␊
      1 error generated.`,
    }

## built-ins/Promise/reject/ctx-ctor.js

> | Test Stage | Status | Details |
> | :-- | :-- | :-- |
> | Load | ✅ Pass |  |
> | Transpile | ❌ Fail | An error occurred while transpiling the test with `@razuberi/transpiler`. |
> | Compile | ⬜ Skip | *This stage did not run.* |
> | Execute | ⬜ Skip | *This stage did not run.* |

    Error {
      message: 'We don\'t know what to do with this node type. We were previously a Statement but we can\'t fit in here?',
    }

## built-ins/Promise/reject/ctx-non-ctor.js

> | Test Stage | Status | Details |
> | :-- | :-- | :-- |
> | Load | ✅ Pass |  |
> | Transpile | ✅ Pass |  |
> | Compile | ✅ Pass |  |
> | Execute | ❌ Fail | An error occurred while executing the test program. |

    Error {
      message: 'Uncaught Test262Error: Expected a undefined but got a different error constructor with the same name',
    }

## built-ins/Promise/reject/ctx-non-object.js

> | Test Stage | Status | Details |
> | :-- | :-- | :-- |
> | Load | ✅ Pass |  |
> | Transpile | ❌ Fail | An error occurred while transpiling the test with `@razuberi/transpiler`. |
> | Compile | ⬜ Skip | *This stage did not run.* |
> | Execute | ⬜ Skip | *This stage did not run.* |

    Error {
      message: 'No generator defined for ArrayExpression nodes.',
    }

## built-ins/Promise/reject/length.js

> | Test Stage | Status | Details |
> | :-- | :-- | :-- |
> | Load | ✅ Pass |  |
> | Transpile | ❌ Fail | An error occurred while transpiling the test with `@razuberi/transpiler`. |
> | Compile | ⬜ Skip | *This stage did not run.* |
> | Execute | ⬜ Skip | *This stage did not run.* |

    Error {
      message: 'We don\'t know what to do with this node type. We were previously a Statement but we can\'t fit in here?',
    }

## built-ins/Promise/reject/name.js

> | Test Stage | Status | Details |
> | :-- | :-- | :-- |
> | Load | ✅ Pass |  |
> | Transpile | ❌ Fail | An error occurred while transpiling the test with `@razuberi/transpiler`. |
> | Compile | ⬜ Skip | *This stage did not run.* |
> | Execute | ⬜ Skip | *This stage did not run.* |

    Error {
      message: 'We don\'t know what to do with this node type. We were previously a Statement but we can\'t fit in here?',
    }

## built-ins/Promise/reject/not-a-constructor.js

> | Test Stage | Status | Details |
> | :-- | :-- | :-- |
> | Load | ✅ Pass |  |
> | Transpile | ❌ Fail | An error occurred while transpiling the test with `@razuberi/transpiler`. |
> | Compile | ⬜ Skip | *This stage did not run.* |
> | Execute | ⬜ Skip | *This stage did not run.* |

    Error {
      message: 'No generator defined for ArrayExpression nodes.',
    }

## built-ins/Promise/reject/prop-desc.js

> | Test Stage | Status | Details |
> | :-- | :-- | :-- |
> | Load | ✅ Pass |  |
> | Transpile | ❌ Fail | An error occurred while transpiling the test with `@razuberi/transpiler`. |
> | Compile | ⬜ Skip | *This stage did not run.* |
> | Execute | ⬜ Skip | *This stage did not run.* |

    Error {
      message: 'We don\'t know what to do with this node type. We were previously a Statement but we can\'t fit in here?',
    }
